Workbook

Sheet Sheet5
A3: Row Labels | B3: Count of discounted_price | C3: Count of actual_price
A4: Car&Motorbike | B4: 1 | C4: 1
A5: Computers&Accessories | B5: 453 | C5: 453
A6: Electronics | B6: 526 | C6: 526
A7: Health&PersonalCare | B7: 1 | C7: 1
A8: Home&Kitchen | B8: 448 | C8: 448
A9: HomeImprovement | B9: 2 | C9: 2
A10: MusicalInstruments | B10: 2 | C10: 2
A11: OfficeProducts | B11: 31 | C11: 31
A12: Toys&Games | B12: 1 | C12: 1
A13: (blank)
A14: Grand Total | B14: 1465 | C14: 1465

Sheet Sheet1
A1: product_id | B1: product_id | C1: product_name | D1: category | E1: discounted_price | F1: actual_price | G1: discount_percentage | H1: rating | I1: rating_count | J1: about_product | K1: user_id | L1: user_name | M1: user_count | N1: review_id | O1: review_title | P1: review_content | Q1: img_link | R1: product_link
A2: =LEFT(B2,LEN(B2)-1) -> B07JW9H4J | B2: B07JW9H4J1 | C2: =CONCATENATE(Sheet2!B2,Sheet2!C2) -> WayonaNylon | D2: Computers&Accessories | E2: $399 | F2: $1,099 | G2: 0.64 | H2: 4.2 | I2: 24269 | J2: High Compatibility : Compatible With iPhone 12, 11, X/XsMax/Xr ,iPhone 8/8 Plus,iPhone 7/7 Plus,iPhone 6s/6s Plus,iPhone 6/6 Plus,iPhone 5/5s/5c/se,iPad Pro,iPad Air 1/2,iPad mini 1/2/3,iPod nano7,iPod touch and more apple devices.|Fast Charge&Data Sync : It can charge and sync simultaneously at a rapid speed, Compatible with any charging adaptor, multi-port charging station or power bank.|Durability : Durable nylon braided design with premium aluminum housing and toughened nylon fiber wound tightly around the cord lending it superior durability and adding a bit to its flexibility.|High Security Level : It is designed to fully protect your device from damaging excessive current.Copper core thick+Multilayer shielding, Anti-interference, Protective circuit equipment.|WARRANTY: 12 months warranty and friendly customer services, ensures the long-time enjoyment of your purchase. If you meet any question or problem, please don't hesitate to contact us. | K2: AG3D6O4STAQKAY2UVGEUV46KN35Q,AHMY5CWJMMK5BJRBBSNLYT3ONILA,AHCTC6ULH4XB6YHDY6PCH2R772LQ,AGYHHIERNXKA6P5T7CZLXKVPT7IQ,AG4OGOFWXJZTQ2HKYIOCOY3KXF2Q,AENGU523SXMOS7JPDTW52PNNVWGQ,AEQJHCVTNINBS4FKTBGQRQTGTE5Q,AFC3FFC5PKFF5PMA52S3VCHOZ5FQ | L2: =CONCATENATE(Sheet4!B2,Sheet4!C2) -> ManavAdarsh gupta | M2: =COUNTA(Sheet4!B2:K2) -> 8 | N2: R3HXWT0LRP0NMF,R2AJM3LFTLZHFO,R6AQJGUP6P86,R1KD19VHEDV0OR,R3C02RMYQMK6FC,R39GQRVBUZBWGY,R2K9EDOE15QIRJ,R3OI7YT648TL8I | O2: Satisfied,Charging is really fast,Value for money,Product review,Good quality,Good product,Good Product,As of now seems good | P2: Looks durable Charging is fine tooNo complains,Charging is really fast, good product.,Till now satisfied with the quality.,This is a good product . The charging speed is slower than the original iPhone cable,Good quality, would recommend,https://m.media-amazon.com/images/W/WEBP_402378-T1/images/I/81---F1ZgHL._SY88.jpg,Product had worked well till date and was having no issue.Cable is also sturdy enough...Have asked for replacement and company is doing the same...,Value for money | Q2: https://m.media-amazon.com/images/W/WEBP_402378-T1/images/I/51UsScvHQNL._SX300_SY300_QL70_FMwebp_.jpg | R2: https://www.amazon.in/Wayona-Braided-WN3LG1-Syncing-Charging/dp/B07JW9H4J1/ref=sr_1_1?qid=1672909124&s=electronics&sr=1-1
A3: =LEFT(B3,LEN(B3)-1) -> B098NS6PV | B3: B098NS6PVG | C3: =CONCATENATE(Sheet2!B3,Sheet2!C3) -> AmbraneUnbreakable | D3: Computers&Accessories | E3: $199 | F3: $349 | G3: 0.43 | H3: 4 | I3: 43994 | J3: Compatible with all Type C enabled devices, be it an android smartphone (Mi, Samsung, Oppo, Vivo, Realme, OnePlus, etc), tablet, laptop (Macbook, Chromebook, etc)|Supports Quick Charging (2.0/3.0)|Unbreakable â€“ Made of special braided outer with rugged interior bindings, it is ultra-durable cable that wonâ€™t be affected by daily rough usage|Ideal Length â€“ It has ideal length of 1.5 meters which is neither too short like your typical 1meter cable or too long like a 2meters cable|Supports maximum 3A fast charging and 480 Mbps data transfer speed|6 months manufacturer warranty from the date of purchase | K3: AECPFYFQVRUWC3KGNLJIOREFP5LQ,AGYYVPDD7YG7FYNBXNGXZJT525AQ,AHONIZU3ICIEHQIGQ6R2VFRSBXOQ,AFPHD2CRPDZMWMBL7WXRSVYWS5JA,AEZ346GX3HJ4O4XNRPHCNHXQURMQ,AEPSWFPNECKO34PUC7I56ITGXR6Q,AHWVEHR5DYLVFTO2KF3IZATFQSWQ,AH4QT33M55677I7ISQOAKEQWACYQ | L3: =CONCATENATE(Sheet4!B3,Sheet4!C3) -> ArdKnNirbhay kumar | M3: =COUNTA(Sheet4!B3:K3) -> 8 | N3: RGIQEG07R9HS2,R1SMWZQ86XIN8U,R2J3Y1WL29GWDE,RYGGS0M09S3KY,R17KQRUTAN5DKS,R3AAQGS6HP2QUK,R1HDNOG6TO2CCA,R3PHKXYA5AFEOU | O3: A Good Braided Cable for Your Type C Device,Good quality product from ambrane,Super cable,As,Good quality,Good product,its good,Good quality for the price but one issue with my unit | P3: I ordered this cable to connect my phone to Android Auto of car. The cable is really strong and the connection ports are really well made. I already has a Micro USB cable from Ambrane and it's still in good shape. I connected my phone to the car using the cable and it got connected well and no issues. I also connected it to the charging port and yes it has Fast Charging support.,It quality is good at this price and the main thing is that i didn't ever thought that this cable will be so long it's good one and charging power is too good and also supports fast charging,Value for money, with extra lengthðŸ‘,Good, working fine,Product quality is good,Good,very good,Bought for my daughter's old phone.Brand new cable it was not charging, I already repacked and requested for replacement.I checked again, and there was some green colour paste/fungus inside the micro USB connector. I cleaned with an alcoholic and starts working again.Checked the ampere of charging speed got around 1400ma-1500ma - not bad, came with braided 1.5m long cable, pretty impressive for the price.Can't blame the manufacturer.But quality issues by the distributor, they might have stored in very humid place. | Q3: https://m.media-amazon.com/images/W/WEBP_402378-T2/images/I/31zOsqQOAOL._SY445_SX342_QL70_FMwebp_.jpg | R3: https://www.amazon.in/Ambrane-Unbreakable-Charging-Braided-Cable/dp/B098NS6PVG/ref=sr_1_2?qid=1672909124&s=electronics&sr=1-2
A4: =LEFT(B4,LEN(B4)-1) -> B096MSW6C | B4: B096MSW6CT | C4: =CONCATENATE(Sheet2!B4,Sheet2!C4) -> SounceFast | D4: Computers&Accessories | E4: $199 | F4: $1,899 | G4: 0.9 | H4: 3.9 | I4: 7928 | J4: ã€ Fast Charger& Data Syncã€‘-With built-in safety proctections and four-core copper wires promote maximum signal quality and strength and enhance charging & data transfer speed with up to 480 mb/s transferring speed.|ã€ Compatibilityã€‘-Compatible with iPhone 13, 12,11, X, 8, 7, 6, 5, iPad Air, Pro, Mini & iOS devices.|ã€ Sturdy & Durableã€‘-The jacket and enforced connector made of TPE and premium copper, are resistant to repeatedly bending and coiling.|ã€ Ultra High Qualityã€‘: According to the experimental results, the fishbone design can accept at least 20,000 bending and insertion tests for extra protection and durability. Upgraded 3D aluminum connector and exclusive laser welding technology, which to ensure the metal part won't break and also have a tighter connection which fits well even with a protective case on and will never loose connection.|ã€ Good After Sales Serviceã€‘-Our friendly and reliable customer service will respond to you within 24 hours ! you can purchase with confidence,and every sale includes a 365-day worry-free Service to prove the importance we set on quality. | K4: AGU3BBQ2V2DDAMOAKGFAWDDQ6QHA,AESFLDV2PT363T2AQLWQOWZ4N3OA,AHTPQRIMGUD4BYR5YIHBH3CCGEFQ,AEUVWXYP5LT7PZLLZENEO2NODPBQ,AHC7MPW55DOO6WNCOQVA2VHOD26A,AFDI6FRPFBTNBG7BAEB7JDJSMKDQ,AFQKCEEEKXCOHTDG4WUN3XPPHJQQ,AHKUUFNMBZIDLSSPA4FEHIO2EC7Q | L4: =CONCATENATE(Sheet4!B4,Sheet4!C4) -> KunalHimanshu | M4: =COUNTA(Sheet4!B4:K4) -> 8 | N4: R3J3EQQ9TZI5ZJ,R3E7WBGK7ID0KV,RWU79XKQ6I1QF,R25X4TBMPY91LX,R27OK7G99VK0TR,R207CYDCHJJTCJ,R3PCU8XMU173BT,R1IMONDOWRNU5V | O4: Good speed for earlier versions,Good Product,Working good,Good for the price,Good,Worth for money,Working nice,it's a really nice product | P4: Not quite durable and sturdy,https://m.media-amazon.com/images/W/WEBP_402378-T1/images/I/71rIggrbUCL._SY88.jpg,Working good,https://m.media-amazon.com/images/W/WEBP_402378-T1/images/I/61bKp9YO6wL._SY88.jpg,Product,Very nice product,Working well,It's a really nice product | Q4: https://m.media-amazon.com/images/W/WEBP_402378-T1/images/I/31IvNJZnmdL._SY445_SX342_QL70_FMwebp_.jpg | R4: https://www.amazon.in/Sounce-iPhone-Charging-Compatible-Devices/dp/B096MSW6CT/ref=sr_1_3?qid=1672909124&s=electronics&sr=1-3
A5: =LEFT(B5,LEN(B5)-1) -> B08HDJ86N | B5: B08HDJ86NZ | C5: =CONCATENATE(Sheet2!B5,Sheet2!C5) -> boAtDeuce | D5: Computers&Accessories | E5: $329 | F5: $699 | G5: 0.53 | H5: 4.2 | I5: 94363 | J5: The boAt Deuce USB 300 2 in 1 cable is compatible with smartphones, tablets, PC peripherals, Bluetooth speakers, power banks and all other devices with Type-C as well as Micro USB port|It ensures 3A fast charging and data transmissions with rapid sync at 480 mbps|The premium Nylon braided skin makes it sturdy and invincible against external damage|Its Aluminium alloy shell housing makes it last longer with 10000+ Bends Lifespan with extended frame protection for strain relief|The resilient and flexible design offers a tangle free experience seamlessly|Deuce USB 300 cable offers a perfect 1.5 meters in length for smooth & hassle-free user experience|2 years warranty from the date of purchase | K5: AEWAZDZZJLQUYVOVGBEUKSLXHQ5A,AG5HTSFRRE6NL3M5SGCUQBP7YSCA,AH725ST5NW2Y4JZPKUNTIJCUK2BA,AHV3TXIFCJPMS4D5JATCEUR266MQ,AGWIGDEMFIIUAOXYY2QATNBSUGHA,AFSTSLQUV4EVEXWKBOLEFHL2H5YQ,AGAKDNBHY2FKX7I4ACRGILU7QL7A,AFNWJUWJRHCC6HN52KMG5AKZY37Q | L5: =CONCATENATE(Sheet4!B5,Sheet4!C5) -> Omkar dhaleJD | M5: =COUNTA(Sheet4!B5:K5) -> 8 | N5: R3EEUZKKK9J36I,R3HJVYCLYOY554,REDECAZ7AMPQC,R1CLH2ULIVG5U3,R2DMKIBGFKBD6R,RC89B5IAJUTR5,R3B3DDON5FH8DS,R13WAEJDI5RS36 | O5: Good product,Good one,Nice,Really nice product,Very first time change,Good,Fine product but could be better,Very nice it's charging like jet | P5: Good product,long wire,Charges good,Nice,I bought this cable for Rs.339 worthy product for this price, i tested it in various charger adapters 33w and 18w it supports fast charging as well.,Good,Ok,I had got this at good price on sale on Amazon and product is useful with warranty but for warranty you need to go very far not practical for such a cost and mine micro to type c connector stopped working after few days only.,I like this product | Q5: https://m.media-amazon.com/images/I/41V5FtEWPkL._SX300_SY300_QL70_FMwebp_.jpg | R5: https://www.amazon.in/Deuce-300-Resistant-Tangle-Free-Transmission/dp/B08HDJ86NZ/ref=sr_1_4?qid=1672909124&s=electronics&sr=1-4
A6: =LEFT(B6,LEN(B6)-1) -> B08CF3B7N | B6: B08CF3B7N1 | C6: =CONCATENATE(Sheet2!B6,Sheet2!C6) -> PortronicsKonnect | D6: Computers&Accessories | E6: $154 | F6: $399 | G6: 0.61 | H6: 4.2 | I6: 16905 | J6: [CHARGE & SYNC FUNCTION]- This cable comes with charging & Data sync function|[HIGH QUALITY MATERIAL]- TPE + Nylon Material to make sure that the life of the cable is enhanced significantly|[LONG CORD]- The Cable is extra thick 1.2 meter long, optimized for an easy use for your comfort at home or office|[MORE DURABLE]-This cable is unique interms of design and multi-use and is positioned to provide the best comfort and performance while using|[UNIVERSAL COMPATIBILITY]- Compatible with all devices like iPhone XS, X, XR, 8, 7, 6S, 6, 5S, iPad Pro, iPad mini and iPad Air | K6: AE3Q6KSUK5P75D5HFYHCRAOLODSA,AFUGIFH5ZAFXRDSZHM4QB2KPKFUQ,AFK4NJOLFSJGWLOJIUIAROJF6YVA,AFUOTYRFUXVPEBGIXVZZ7DR3CZUA,AFDLRSXKDZ6U3U3KD46SQLFGZQRA,AH5VLM66SIK7J3IRG4NY7XVOQ55A,AE3MQNNHHLUHXURL5S7IAR7JTGNQ,AFSEOFZY67MYC7UAJU264Z5NFTLA | L6: =CONCATENATE(Sheet4!B6,Sheet4!C6) -> rahuls6099Swasat Borah | M6: =COUNTA(Sheet4!B6:K6) -> 8 | N6: R1BP4L2HH9TFUP,R16PVJEXKV6QZS,R2UPDB81N66T4P,R3KK4GT934ST3I,RCFHMWUSBIJO,RDO7DACXMAJ84,R3A6MEZL3LY66Z,R1ESIEKPGAYA29 | O6: As good as original,Decent,Good one for secondary use,Best quality,GOOD,Amazing product at a mind blowing price!,Nice Quality,Good product | P6: Bought this instead of original apple, does the work for 150rs, not as fast as apple charger but its a good option if you want cheap and good product, bought it for iPad pro 10.5 and it's working flawlessly, build quality is ok, its not like i am gonna hang my clothes on it and i want a very strong cable, even a braided cable stop working after a year, i have used both Anker and Apple store strong braided cable they all stop working after a year so please don't buy high end cables just for that instead choose a this one and even if it's stops working withing a year you only loose 150rs compares to 2000rs.UPDATE------------------------------------pin has stopped charging from one side, now i have to slip the pin to charge from other side, but i will update and let know for how long does it work,,Itâ€™s good. Not sure about durability as the pin area feels a bit fragile,Does not support apple carplaySo was little disappointed about thatOther than that cable is made up of very good quality,Best to buy,100% NOT FATHFUL,Writing this review post 10 months and 3 orders of the same product.Honestly Portronics Konnect L lightning cable works like magic with the original Apple charging brick.Seeing the price of the cable I initially hesitated buying as it was as low as â‚¹99/- with the offers and so I wasnâ€™t sure if it would work well with my iPhone 12 or whether it would impact my iPhoneâ€™s battery health because all the other lightning cable brands were costing over â‚¹350/- like Wayona, Amazon Basics, etc.Earlier I was using Wayona Brand lightning cable with eventually frayed and stopped working.Charging Speed:Charges my iPhone fast enough almost similar compared to the original cable level when used with 12W Original Apple power adapter.Quality and Durability:Great quality braided cable and doesnâ€™t tangle easily and can withstand day-to-day usage.L-Shaped pin:This is very innovative by Portronics and it makes sure the cable doesnâ€™t get damaged even if used while charging.CarPlay and Data Sync:Works smoothly with CarPlay and syncs data effortlessly.PS: I have used this cable only with the Original Apple Charging Brick and extremely satisfied with its performance.,Better than I expect the product I like that Quality and I plan to buy same type cable come with usb C to Lighting cable for emergency purpose that much I love this cable. Buy for this cable only emergency uses only since Good one,Good product and value for money | Q6: https://m.media-amazon.com/images/W/WEBP_402378-T2/images/I/31VzNhhqifL._SX300_SY300_QL70_FMwebp_.jpg | R6: https://www.amazon.in/Portronics-Konnect-POR-1080-Charging-Function/dp/B08CF3B7N1/ref=sr_1_5?qid=1672909124&s=electronics&sr=1-5
A7: =LEFT(B7,LEN(B7)-1) -> B08Y1TFSP | B7: B08Y1TFSP6 | C7: =CONCATENATE(Sheet2!B7,Sheet2!C7) -> pTronSolero | D7: Computers&Accessories | E7: $149 | F7: $1,000 | G7: 0.85 | H7: 3.9 | I7: 24871 | J7: Fast Charging & Data Sync: Solero TB301 Type-C cable supports fast charge up to 5V/3A for devices and data syncing speed up to 480Mbps.|Universal Compatibility: This USB charging cable connects USB Type-C devices with standard USB devices like laptops, hard drives, power banks, wall and car chargers, etc..Connector One: Reversible Type C|Connector Two: USB A Type|Rough & Tough Type-C Cable: Charging cable with a double-braided exterior, premium aramid fiber core and metal plugs. It has passed 10,000 bending tests and can easily withstand daily use.|Extended Length: 1.5-meter long c-type cable uses nylon material to protect the wire and avoid knots.|Perfect Fit Connectors: pTron Soler USB-C has passed the 5KG load test, swing test, 5000+ times connect & disconnect to ensure that there are no loose connections. | K7: AEQ2YMXSZWEOHK2EHTNLOS56YTZQ,AGRVINWECNY7323CWFXZYYIZOFTQ,AHBAT6VLOXWGYDL57KHCNCLPXAKA,AF7NDY2H6JVYTSQOZP76GCATQ34Q,AFV7ZA733ZLME4KNLZPMPCBUNPPA,AHFAAPSY2MJ5HYOU2VQDJ7AQY4NQ,AH2WGV2PEBUTICRPBEEVKF24G5LA,AEP4MK3EKOBDKTGPJTRN5RBDIODA | L7: =CONCATENATE(Sheet4!B7,Sheet4!C7) -> JayeshRajesh k. | M7: =COUNTA(Sheet4!B7:K7) -> 9 | N7: R7S8ANNSDPR40,R3CLZFLHVJU26P,RFF7U7MPQFUGR,R1MV1NKC23DWPI,R11D3U0V2XKDKF,R18MP1KLUE18PC,RWGJNVEH5ZQME,R1XN72FU6Q37IH | O7: It's pretty good,Average quality,very good and useful usb cable,Good USB cable. My experience was very good it is long lasting,Good,Nice product and useful,-,Sturdy but does not support 33w charging | P7: It's a good product.,Like,Very good item strong and useful USB cableValue for moneyThanks to amazon and producer,https://m.media-amazon.com/images/I/51112ZRE-1L._SY88.jpg,Good,Nice product and useful product,-,Sturdy but does not support 33w charging | Q7: https://m.media-amazon.com/images/I/31wOPjcSxlL._SX300_SY300_QL70_FMwebp_.jpg | R7: https://www.amazon.in/Solero-TB301-Charging-480Mbps-1-5-Meter/dp/B08Y1TFSP6/ref=sr_1_6?qid=1672909124&s=electronics&sr=1-6
A8: =LEFT(B8,LEN(B8)-1) -> B08WRWPM2 | B8: B08WRWPM22 | C8: =CONCATENATE(Sheet2!B8,Sheet2!C8) -> boAtMicro | D8: Computers&Accessories | E8: $176.63 | F8: $499 | G8: 0.65 | H8: 4.1 | I8: 15188 | J8: It Ensures High Speed Transmission And Charging By Offering 3A Fast Charging And Data Transmissions With Rapid Sync At 480 Mbps|The Braided Skin Makes It Durable And Invincible Against External Damage So You Can Have An Absolute Hassle-Free & Tangle Free Experience|Its Durable Pvc Housing And The Flexible Design Makes It Last 6 Times Longer Than Other Cables|Usb Cable Offers A Perfect 1.5 Meters In Length For Smooth & Hassle-Free User Experience For Superior Charging & Data Transfer Tasks|The Compact And Smooth Aluminium Connector Fits Most Cases Seamlessly And Resists Corrosion For Signal Purity|Micro Usb 55 Cable Offers Universal Compatibility As It Is Compatible With Most Android Smartphones, Tablets, Pc Peripherals, Bluetooth Speakers, Power Banks, Game Consoles & All Micro-Usb Enabled Devices|2 years warranty from the date of purchase | K8: AG7C6DAADCTRQJG2BRS3RIKDT52Q,AFU7BOMPVJ7Q3TTA4G67RASTGYIQ,AER5ZGIXXVYG3AWZTRZT7M2BYCEA,AHE76XQSOLGOP5ZEKTIW6KUPDWBQ,AGXTMB2XHZBEWZ2UIX7ODZ4XTU6Q,AHNM2XVU745EDPNGUOAG74PTSNRA,AH5RWQ4S72IVLZD6O75OPCFIVDXQ,AG322TYKVPLPBDXE7ABEUK5QTALQ | L8: =CONCATENATE(Sheet4!B8,Sheet4!C8) -> Vivek kumarAmazon Customer | M8: =COUNTA(Sheet4!B8:K8) -> 8 | N8: R8E73K2KWJRDS,RSD0JTIIWQQL8,R64CRSTE9SLW1,R2FRTNIIUFJE1F,RWGNX3W7UOJ7W,R32TYHHODHTF5D,RQL9ZMQUTY7P2,R280XJ5VZUBOXV | O8: Long durable.,good,Does not charge Lenovo m8 tab,Best charging cable,good,Boat,Product was good,1.5 m à¤•à¤¾ à¤•à¥‡à¤¬à¤² à¤®à¥‡à¤°à¥‡ à¤²à¤¿à¤ à¤¬à¤¹à¥à¤¤ à¤¹à¥€ à¤²à¤¾à¤­à¤¦à¤¾à¤¯à¤• à¤¹à¥ˆ à¥¤ | P8: Build quality is good and it is comes with 2 year warranty.,Good Product,Bought it for charging my mobile & tab but it doesn't work for Lenovo m8 tab,Guys this cable is is best compare of everyone over heat protection, quickly charging, but chance to shock circuit,good,Nice,Good quality,1.5à¤à¤® à¤•à¤¾ à¤¡à¤¾à¤Ÿà¤¾ à¤•à¥‡à¤¬à¤² à¤®à¥‡à¤°à¥‡ à¤²à¤¿à¤ à¤¬à¤¹à¥à¤¤ à¤¹à¥€ à¤²à¤¾à¤­à¤¦à¤¾à¤¯à¤• à¤¹à¥ˆ à¥¤ à¤®à¥ˆà¤‚ à¤‡à¤¸ à¤•à¥‡à¤¬à¤² à¤•à¥‹ à¤²à¤¾à¤‡à¤¨ à¤®à¥‡à¤‚ à¤šà¤¾à¤°à¥à¤œ à¤•à¤°à¤¤à¥‡ à¤¸à¤®à¤¯ à¤«à¥‹à¤¨ à¤¬à¤¹à¥à¤¤ à¤†à¤°à¤¾à¤® à¤¸à¥‡ à¤‰à¤ªà¤¯à¥‹à¤— à¤•à¤° à¤ªà¤¾ à¤°à¤¹à¤¾ à¤¹à¥ à¥¤ à¤†à¤ª à¤‡à¤¸ à¤•à¥‡à¤¬à¤² à¤¸à¥‡ 15watt à¤•à¤¾ à¤šà¤¾à¤°à¥à¤œà¤° à¤‰à¤¸à¥‡ à¤•à¤° à¤¸à¤•à¤¤à¥‡ à¤¹à¥ˆ (à¤‡à¤¸à¤¸à¥‡ à¤œà¤¡à¤¼à¤¾ à¤¨à¤¹à¥€) à¥¤ à¤²à¥‹à¤•à¤² à¤¬à¤¾à¤œà¤¾à¤° à¤®à¥‡à¤‚ à¤‡à¤¸à¤•à¤¾ à¤¦à¤¾à¤® 150 à¤¹à¥ˆ , à¤…à¤®à¥‡à¤œà¤¨ à¤ªà¥‡ à¤¯à¥‡ à¤•à¥‡à¤¬à¤² à¤®à¥à¤à¥‡ 67 à¤®à¥‡à¤‚ à¤®à¤¿à¤²à¤¾ à¥¤ à¤—à¤°à¥à¤µ à¤¸à¥‡ à¤•à¤¹à¥‹ à¤¹à¤® à¤¹à¤¿à¤‚à¤¦à¥‚ à¤¹à¥ˆ , à¤œà¤¯ à¤¹à¤¿à¤‚à¤¦ à¤œà¤¯ à¤­à¤¾à¤°à¤¤ , | Q8: https://m.media-amazon.com/images/W/WEBP_402378-T2/images/I/41jlwEZpa5L._SX300_SY300_QL70_FMwebp_.jpg | R8: https://www.amazon.in/boAt-Micro-USB-Tangle-Free-Transmission/dp/B08WRWPM22/ref=sr_1_8?qid=1672909124&s=electronics&sr=1-8
A9: =LEFT(B9,LEN(B9)-1) -> B08DDRGWT | B9: B08DDRGWTJ | C9: =CONCATENATE(Sheet2!B9,Sheet2!C9) -> MIUsb | D9: Computers&Accessories | E9: $229 | F9: $299 | G9: 0.23 | H9: 4.3 | I9: 30411 | J9: 1m long Type-C USB Cable|Sturdy and Durable. With USB cable you can transfer data with speeds of upto 480 Mbps|Upto 3A output|6months warranty|Sturdy and Durable. With USB cable you can transfer data with speeds of upto 480 Mbps|6months warranty|Up To 3A Output | K9: AHW6E5LQ2BDYOIVLAJGDH45J5V5Q,AF74RSGCHPZITVFSZN76K6GKPICA,AHDD7ZNB47QA2JLYU53HD4ML3VNQ,AHV3ELGDSOWBYUQLXSPDCSHBQRHQ,AEJU4L3ZM2GTILSJZZSNSF6VUOIA,AFVD66VQMSHPDT3A6HBBBGKRXBZA,AELKHQXVSSG6NHXLFJLLNEFRQQUQ,AGYSMAC6V6RFJJOHG2FIRPOZ6CSQ | L9: =CONCATENATE(Sheet4!B9,Sheet4!C9) -> Pavan A HJayesh bagad | M9: =COUNTA(Sheet4!B9:K9) -> 8 | N9: R2X090D1YHACKR,R32ZCIH9AFNJ60,R3N57EVVG0EHAF,R3QWLE8JHROKC1,R2VTSDOOUTSQ5X,R3E6FZ75Q074KH,R1SYBQLTPFCW20,RYQT96J8HPIXE | O9: Worth for money - suitable for Android auto,Good Product,Length,Nice,Original,Very good quay Cable support fast charging.,Original MI cable for charging upto 33 watt,I am veri happy with this product as it provide turbo charging. | P9: Worth for money - suitable for Android auto... my purpose served in car....got it for Rs.150,Everything is Okay. But packaging is not good feeling like seller gave is used cable.,Good product,Good product but cost is more.,Original cable,I bought this cable at 129. Using this cable for Android auto in my car. Perfectly works without any glitch.,Original MI cable. Will charge upto 33 watts. Got it for Rs 150. I have 67 watt charger and I want a cable for my car so I went for it. I checked the performance with battery charging app. The charging speed is exactly half of my 67 watt original cable. Go for it.,It provided me turbo charging. I recommend for all Redmi note 10s mobile phones. As it provide turbo charging. I am veri happy with this product. | Q9: https://m.media-amazon.com/images/I/31XO-wfGGGL._SX300_SY300_QL70_FMwebp_.jpg | R9: https://www.amazon.in/MI-MTCY001IN-USB-Type-C-Cable/dp/B08DDRGWTJ/ref=sr_1_9?qid=1672909124&s=electronics&sr=1-9
A10: =LEFT(B10,LEN(B10)-1) -> B008IFXQF | B10: B008IFXQFU | C10: =CONCATENATE(Sheet2!B10,Sheet2!C10) -> TP-LinkUSB | D10: Computers&Accessories | E10: $499 | F10: $999 | G10: 0.5 | H10: 4.2 | I10: 1,79,691 | J10: USB WiFi Adapter â€”â€” Speedy wireless transmission at up to 150Mbps ideal for video streaming or internet calls|Mini Design â€”â€” Sleek miniature design so small that once plugged in, can be left in a Laptopâ€™s USB port|Advanced Security â€”â€” Supports 64/128 WEP, WPA, PA2/WPA-PSK/WPA2-PSK(TKIP/AES)|Compatibility â€”â€” Windows 11/10/8.1/8/7/XP, Mac OS 10.15 and earlier, Linux|Easy Setup â€”â€” Connect in no time with easy setup utility in 14 languages|In an unlikely case of product quality related issue, we may ask you to reach out to brandâ€™s customer service support and seek resolution. We will require brand proof of issue to process replacement request | K10: AGV3IEFANZCKECFGUM42MRH5FNOA,AEBO7NWCNXKT4AESAN443HQH35FQ,AE7GD3VRRYQEAHDR7FXJIR23INYA,AHPAW24BI5X2GCX5M2LHI72VSJJQ,AE2VXY4CFO36MDSIMPG43XHNF4GA,AHHQEKUNVETALN7DTRHUQ2WAWEKQ,AFMIFTNTUD5PIHGONWOTRMMZ5EBA,AHOJBIZVVIIFJKRREY4B6ESVA4KA | L10: =CONCATENATE(Sheet4!B10,Sheet4!C10) -> Azhar JuManAnirudh Sood | M10: =COUNTA(Sheet4!B10:K10) -> 8 | N10: R1LW6NWSVTVZ2H,R3VR5WFKUS15C5,R2F6GC79OYWUKQ,R3QZ19MECGWG9A,R2MPU42MYK7GPO,R33DVXFB4VYPZZ,R1SQ7OGFR4JRUR,R1S5F9QI0M1VBZ | O10: Works on linux for me. Get the model with antenna.,Does what it say but other brands available at lesser price,Easy Handle,Great product,Perfect working,Speed is perfect,Great Design, Build, Connectivity Range, Packaging and other features but no linux support since v2,Very good | P10: I use this to connect an old PC to internet. I tried lubuntu 20 and ubuntu 22, it worked out of the box in both, didn't have to do any setup. There's an extender cable so you can place this in a comfortable place. Get the model with antenna because otherwise you'll have range problems if you're not directly in line of sight from your wifi router.,The wifi dongle is a simple plug & play device, will start catching available networks right after you plug it into your USB port, no additional installations/ softwares requires. Signal strength is good.... just wonder what would be different in other adapters of lesser known brands which are available at a much more competitive pricing, hence a star less.,Pros:*Easy to use & Portable*Can be connected to Mobile Hotspot and used in PC( Budget Friendly)*Less installation process*No heating issues & Good Coverage*Best alternative for USB Tethering (phone's battery may get damaged for long term run with Tethering)Cons:*Internet connection speed varies at times, also depends on your modem or cellular connection*Issues occur while installing via CD, which is available along with the product( Installation driver can be downloaded from TP-Link site)*Needed to reconnect the adapter every time system is turned ON*Will not work if your software has some issues, so encountered any just update your system(worked for me)*Support Center is worse, calls are unattended most of the times or just visit nearby storeConclusion:Brought this @499/-Ideal for users who don't need very high speed internet usage,a good alternative for USB Tethering and are on Budge(1080p Youtube videos can be easily played with this without any interruptions),wifi connectivity is a great good result for me. however, some jitter problems did exist.,This is perfect device to connect wifi. Go for it.,This wifi adopter is good working,(Pictures attached)Size/Design: â˜… â˜… â˜… â˜… â˜…Build Quality: â˜… â˜… â˜… â˜… â˜…Packaging: â˜… â˜… â˜… â˜… â˜…Software: â˜… â˜… â˜… â˜…Speed: â˜… â˜… â˜… â˜… â˜…Connectivity: â˜… â˜… â˜… â˜… â˜…Experience: â˜… â˜… â˜… â˜… â˜…Warranty: â˜… â˜… â˜… â˜… â˜…Size and Design:The best part about this is that it is very compact in size and very sober and elegant in design. This is a big plus as it is easy plug in and use, add to it the good sober design.Build Quality:The build quality is undoubtedly superb. Just no qualms about that, at all. When held, it doesnt give off that cheap and flimsy product-like feeling. It is good sturdy with its build quality.Packaging:This part is also a big plus as the item was well cushioned and packaged with all the necessary items that ensured that no damage could have been caused to the product during transportation. This ensures that I as a customer have received something not damaged internally already.Software:This is actually good but not great part with the product.The good part is that a CD has been provided with it along with a manual.The not great part is that NO LINUX SUPPORT has been given from Version 2 onwards. This is bad, really.Speed:It easily supports net speeds upto 300 Mbps. Practically speaking, I have tested it at my home and it easily supports net speed of over 100-150 Mbps without a sigh.On testing I found that it did connect to 5GHz network, without any issue.Connectivity:Please mark its not feet its metres. Multiply metres x 3 to get the distance in feet.It easily connects to my laptop or phone from 7 metres across one room. So thats 21 feet. I mean even our old bluetooth used to connect to about 15 ft.So 20-25 feet is not at all an issue with this. This is the big plus I found with the product.Experience:From this point of view, so far except the linux non-compatibility issue, I found no other flaws with this product.So overall its a great product.Warranty:Its 3 years so I am assured that atleast for 3 years I am tension-free and not just 1 year, contrary to most electronic items today that only provide 1 year warranty with their items.,Best adapter I have bought ever. Works nicely seemless connectivity | Q10: https://m.media-amazon.com/images/W/WEBP_402378-T2/images/I/31e6ElWRymL._SX300_SY300_QL70_FMwebp_.jpg | R10: https://www.amazon.in/TP-Link-TL-WN725N-150Mbps-Wireless-Adapter/dp/B008IFXQFU/ref=sr_1_10?qid=1672909124&s=electronics&sr=1-10
A11: =LEFT(B11,LEN(B11)-1) -> B082LZGK3 | B11: B082LZGK39 | C11: =CONCATENATE(Sheet2!B11,Sheet2!C11) -> AmbraneUnbreakable | D11: Computers&Accessories | E11: $199 | F11: $299 | G11: 0.33 | H11: 4 | I11: 43994 | J11: Universal Compatibility â€“ It is compatible with all Micro USB enabled devices, be it an android smartphone, tablet, PC peripheral or any other micro USB compatible device|Unbreakable â€“ Made of special braided outer with rugged interior bindings, it is ultra-durable cable that wonâ€™t be affected by daily rough usage|Ideal Length â€“ It has ideal length of 1.5 meters which is neither too short like your typical 1meter cable or too long like a 2meters cable|Supports maximum 3A fast charging and 480 Mbps data transfer speed|6 Months manufacturer warranty from the date of purchase. | K11: AECPFYFQVRUWC3KGNLJIOREFP5LQ,AGYYVPDD7YG7FYNBXNGXZJT525AQ,AHONIZU3ICIEHQIGQ6R2VFRSBXOQ,AFPHD2CRPDZMWMBL7WXRSVYWS5JA,AEZ346GX3HJ4O4XNRPHCNHXQURMQ,AEPSWFPNECKO34PUC7I56ITGXR6Q,AHWVEHR5DYLVFTO2KF3IZATFQSWQ,AH4QT33M55677I7ISQOAKEQWACYQ | L11: =CONCATENATE(Sheet4!B11,Sheet4!C11) -> ArdKnNirbhay kumar | M11: =COUNTA(Sheet4!B11:K11) -> 8 | N11: RGIQEG07R9HS2,R1SMWZQ86XIN8U,R2J3Y1WL29GWDE,RYGGS0M09S3KY,R17KQRUTAN5DKS,R3AAQGS6HP2QUK,R1HDNOG6TO2CCA,R3PHKXYA5AFEOU | O11: A Good Braided Cable for Your Type C Device,Good quality product from ambrane,Super cable,As,Good quality,Good product,its good,Good quality for the price but one issue with my unit | P11: I ordered this cable to connect my phone to Android Auto of car. The cable is really strong and the connection ports are really well made. I already has a Micro USB cable from Ambrane and it's still in good shape. I connected my phone to the car using the cable and it got connected well and no issues. I also connected it to the charging port and yes it has Fast Charging support.,It quality is good at this price and the main thing is that i didn't ever thought that this cable will be so long it's good one and charging power is too good and also supports fast charging,Value for money, with extra lengthðŸ‘,Good, working fine,Product quality is good,Good,very good,Bought for my daughter's old phone.Brand new cable it was not charging, I already repacked and requested for replacement.I checked again, and there was some green colour paste/fungus inside the micro USB connector. I cleaned with an alcoholic and starts working again.Checked the ampere of charging speed got around 1400ma-1500ma - not bad, came with braided 1.5m long cable, pretty impressive for the price.Can't blame the manufacturer.But quality issues by the distributor, they might have stored in very humid place. | Q11: https://m.media-amazon.com/images/W/WEBP_402378-T2/images/I/31kj3q4SepL._SY445_SX342_QL70_FMwebp_.jpg | R11: https://www.amazon.in/Ambrane-Unbreakable-Charging-Braided-Android/dp/B082LZGK39/ref=sr_1_11?qid=1672909124&s=electronics&sr=1-11
A12: =LEFT(B12,LEN(B12)-1) -> B08CF3D7Q | B12: B08CF3D7QR | C12: =CONCATENATE(Sheet2!B12,Sheet2!C12) -> PortronicsKonnect | D12: Computers&Accessories | E12: $154 | F12: $339 | G12: 0.55 | H12: 4.3 | I12: 13391 | J12: [CHARGE & SYNC FUNCTION]- This cable comes with charging & Data sync function for smartphones|[HIGH QUALITY MATERIAL]- TPE + Nylon Material to make sure that the life of the cable is enhanced significantly|[LONG CORD]- The Cable is extra thick 1.2 meter long, optimized for an easy use for your comfort at home or office|[MORE DURABLE]-This cable is unique interms of design and multi-use and is positioned to provide the best comfort and performance while using | K12: AGYLPKPZHVYKKZHOTHCTYVEDAJ4A,AGTTU64JMX722LYCN3SOWLFPKPAQ,AFWD4ZTM7473CDWARHCDQKK73MTA,AEXCQM3FDLX3YL3UJWWUIAIUJT4A,AHUKYUWRUVRTB3IQGISXWTSPAWLQ,AFWW4UEXAJH7EAB5LTMKMSGLUN2Q,AFM5JL37WY7G6MLQUI4WAXUJME7Q,AFECO24WYFOU2KL7C3DMHTEHRU7Q | L12: =CONCATENATE(Sheet4!B12,Sheet4!C12) -> TanyaAnu | M12: =COUNTA(Sheet4!B12:K12) -> 8 | N12: R11MQS7WD9C3I0,R2AKH69XQY8BY4,R8GBOLYUN5UP6,R1AYVO4R25KJTA,R1HT6XM787V7FV,R339XJL1GMKHA3,R175VFSB2A32HG,R35T9LXYBSP09G | O12: Good for fast charge but not for data transfer,Good cable compares to local the brand.,good but doesnt last,Good product,Good Product,Good and worth it,very good material quality charging speed is 15 watt,Not a fast charger | P12: The cable is efficient in fast charging but in quick data transfer. Overall fine.,I like the usb c L shape. Nylon Shielded core wire it improves the life of the cable.,i think i buy these every 6 months or so. fast charging stops working after a while. probbly something to do with the cable design. the cable gets twisted over time and I suspect that breaks the high capacity wires inside. but i keep buying it because there arent too many options in an L shaped design,Good and durable product. Sometime the charges doesn't work on few adapters. there might be few cut off or something but works fine on apple adapter, Car charger, USB,The product is really good at affordable price.,Good and fast charging, and value for money,à®ªà¯Šà®°à¯à®³à¯ à®‰à®Ÿà¯ˆà®¯ à®•à®Ÿà®¿à®©à®¤à¯à®¤à®©à¯à®®à¯ˆà®¯à®¿à®©à¯ à®¨à®©à¯à®±à®¾à®• à®‰à®³à¯à®³à®¤à¯ à®šà®¾à®°à¯à®œà¯ à®à®±à¯à®®à¯ à®µà¯‡à®•à®®à¯ 15wat,Not a fast charger. Very slow charging with 65w. L-shape pin is very useful. | Q12: https://m.media-amazon.com/images/I/31dJ+lXJq3L._SY300_SX300_.jpg | R12: https://www.amazon.in/Portronics-POR-1081-Charging-1-2Meter-Function/dp/B08CF3D7QR/ref=sr_1_12?qid=1672909124&s=electronics&sr=1-12
A13: =LEFT(B13,LEN(B13)-1) -> B0789LZTC | B13: B0789LZTCJ | C13: =CONCATENATE(Sheet2!B13,Sheet2!C13) -> boAtRugged | D13: Computers&Accessories | E13: $299 | F13: $799 | G13: 0.63 | H13: 4.2 | I13: 94363 | J13: The boAt rugged cable features our special toughest polyethylene braided jacket and this unique jacket provides greater protection than anything else you have seen in its class. Round Cable|Extra tough polyethylene terephthalate cable skin ensures 10000 plus bend lifespan, stress and stretch resistance|The boAt rugged Micro USB cable is compatible with most android smartphones, windows phone, tablets, PC peripherals and other micro USB compatible devices|2.4A rapid charge, fast data transmission and rapid speed to sync your device at the speed up to 480mbps|boAt rugged micro USB cable offers a perfect 1.5 meters in length, optimized for an easy use for your comfort at home or office|2 years warranty from the date of purchase | K13: AEWAZDZZJLQUYVOVGBEUKSLXHQ5A,AG5HTSFRRE6NL3M5SGCUQBP7YSCA,AH725ST5NW2Y4JZPKUNTIJCUK2BA,AHV3TXIFCJPMS4D5JATCEUR266MQ,AGWIGDEMFIIUAOXYY2QATNBSUGHA,AFSTSLQUV4EVEXWKBOLEFHL2H5YQ,AGAKDNBHY2FKX7I4ACRGILU7QL7A,AFNWJUWJRHCC6HN52KMG5AKZY37Q | L13: =CONCATENATE(Sheet4!B13,Sheet4!C13) -> Omkar dhaleJD | M13: =COUNTA(Sheet4!B13:K13) -> 8 | N13: R3EEUZKKK9J36I,R3HJVYCLYOY554,REDECAZ7AMPQC,R1CLH2ULIVG5U3,R2DMKIBGFKBD6R,RC89B5IAJUTR5,R3B3DDON5FH8DS,R13WAEJDI5RS36 | O13: Good product,Good one,Nice,Really nice product,Very first time change,Good,Fine product but could be better,Very nice it's charging like jet | P13: Good product,long wire,Charges good,Nice,I bought this cable for Rs.339 worthy product for this price, i tested it in various charger adapters 33w and 18w it supports fast charging as well.,Good,Ok,I had got this at good price on sale on Amazon and product is useful with warranty but for warranty you need to go very far not practical for such a cost and mine micro to type c connector stopped working after few days only.,I like this product | Q13: https://m.media-amazon.com/images/I/41SDfuK7L2L._SX300_SY300_QL70_FMwebp_.jpg | R13: https://www.amazon.in/Rugged-Extra-Tough-Unbreakable-Braided/dp/B0789LZTCJ/ref=sr_1_13?qid=1672909124&s=electronics&sr=1-13
A14: =LEFT(B14,LEN(B14)-1) -> B07KSMBL2 | B14: B07KSMBL2H | C14: =CONCATENATE(Sheet2!B14,Sheet2!C14) -> AmazonBasicsFlexible | D14: Electronics | E14: $219 | F14: $700 | G14: 0.69 | H14: 4.4 | I14: 4,26,973 | J14: Flexible, lightweight HDMI cable for connecting media devices to playback display such as HDTVs, projectors, and more|Compatible with Blu-Ray players, computers, Apple TV, Roku, cable, PS4, Xbox One, and other HDMI-compatible devices|Solid copper conductors and full metal jacket shielding for durability and high-performance connectivity|Supports Ethernet, 3D, 4K video and Audio Return Channel (ARC) and meets the latest HDMI standards|Supports bandwidth up to 18Gbps and is backwards compatible with earlier versions|Includes a 3 foot cable | K14: AEYJ5I6JZZPOJB6MGWRQOHRQLPSQ,AFY5TVFOMVHGBPBTIJODYDQRZM5Q,AE3O6366WGEQAANKJ76QETTUQQTQ,AEQIJCPWSBCDKUO5VROXXHWX3PPA,AGVIAQK2HQ47P7UVXHW2NBAEU7YQ,AE3D5CJ2GDUP5SQ3AAYMVAGDTX7A,AH77IQRYD54XCRMCO7XEAIAYCLPA,AEA2HQHMFG3ZGJFOLLJQ65WKIZUQ | L14: =CONCATENATE(Sheet4!B14,Sheet4!C14) -> Rishav GossainShashank Mallamraju | M14: =COUNTA(Sheet4!B14:K14) -> 8 | N14: R1FKOKZ3HHKJBZ,R2WNMZI1EXTA0H,RCA1M3W4RIXUR,R3BKCLL6D7ZLIX,REVSR0ILY3547,R15W5KMQB95IV5,R10PB68FRUHT5V,R3TLCE9JSBU3UP | O14: It's quite good and value for money,Works well,Hdmi cable,Value for money,All good,Gets the job done,Delivery was good,This one was my need to purchase | P14: I am using it for 14 days now. The experience is pretty good as of now. Picture quality is also not bad. Don't expect something out of the world at this price point. But you can go for it if you have a tight budget.,Initial impressions: works as said, glad I didnâ€™t go for cheaper options (not that itâ€™s too costly) just plug and play. Will update if it screws up,The hdmi cable is good to watch movie,sports and its gives better quality while connecting your laptop with TV and play ðŸŽ®.I loved it,Works as expected. Length of the cable is short and it was mentioned also satisfied my requirement. If you need more length better look other options.,All good,It's the best HDMI cable at this price range. No problems yet. Just go for it !!,I was expecting this to be delivered on time and it was delivered on time.Product is good as i have tried other cables and wires from Amazon basica brand.,Good one | Q14: https://m.media-amazon.com/images/I/41nPYaWA+ML._SY300_SX300_.jpg | R14: https://www.amazon.in/AmazonBasics-Flexible-HDMI-Cable-3-Foot/dp/B07KSMBL2H/ref=sr_1_14?qid=1672909124&s=electronics&sr=1-14
A15: =LEFT(B15,LEN(B15)-1) -> B085DTN6R | B15: B085DTN6R2 | C15: =CONCATENATE(Sheet2!B15,Sheet2!C15) -> PortronicsKonnect | D15: Computers&Accessories | E15: $350 | F15: $899 | G15: 0.61 | H15: 4.2 | I15: 2262 | J15: [20W PD FAST CHARGING]-Itâ€™s supports 20W PD quick charge protocol, charge up to 50% in around 30 minutes. It is ideal for charging your USB type c enabled devices at maximum speed|[USB-C to 8 Pin Cable]- Itâ€™s offer rapid charging and syncing between USB Type-C and 8 Pin enabled devices. Safe charging at up to 3A is ensured by high-standard components|[MORE DURABLE]- This cable is unique interms of design and multi-use and is positioned to provide the best comfort and performance while using|[FLEXIBLE CORD]- The Cable uses nylon Braided + Metal Housing material to make sure that the life of the cable is enhanced significantly. It is 4mm extra thick slim 1.2meter long|[UNIVERSAL COMPATIBILITY]-Charge for all Type C USB connectivity devices including MacBook 12 inch, Nexus 5x, Nexus 6p, OnePlus 2, pixel c, Lumia 950, Lumia 950 xl, Nokia n1, etc | K15: AGUAYQHARAKR2VZTRP276KAGETKQ,AFKTST2773VUOKUHE7FCR6QCAURQ,AEGLHOQOWUUUQEDV6EWXTSHIUE7A,AEHQYGI5L4FFALBMC5XMT5KXSZCA,AHJFXFGDAXEHIG2ZLUWVMZ3LWPBA,AEP4CW3UI7AJ7XM7PAAKVCB6U3ZA,AHIWCPCQ2Z4HWEM7V4HGTLVZQM6Q,AHT4JDEYWRIQGCA2WAQJ6E2POHCQ | L15: =CONCATENATE(Sheet4!B15,Sheet4!C15) -> PriyaMansi | M15: =COUNTA(Sheet4!B15:K15) -> 8 | N15: R1QETDIPRCX4S0,RARQYQ8POOFA9,R952F931MCOR5,R3LLDHV3WXED9C,R282YHZ5A4GMY4,R34W3B1C7RP98Q,R1467F9VL3DLSY,R3KLQRR1UM44JG | O15: Works,Nice Product,Fast Charging as original,Good for data transfer,Average. Cost effective,Good quality,Great Product,Nice | P15: Definitely isnâ€™t as good as the original cord but works. Fast charging and pretty sturdy,Worth it,So I had a faulty cable. I was lazy and have a lot of money so instead of calling Apple I bought this for like 300 bucks. Didnâ€™t expected much but for my surprise, this cable actually works and has fast charging. JUST GO FOR IT,Felt quite sturdy, the connectors look premium and were easy to insert. I used this cable to switch all my data from iphone 7 to an m30s. Cable worked like charm while using smart switch app, all my data including whatsapp data was transferred successfully. Satisfied with performance.,Just good,Quality is very goodWorking smoothly.. using same portronics pd charger,This is a real fast charging cable that is serving the purpose,Very good | Q15: https://m.media-amazon.com/images/I/31J6qGhAL9L._SX300_SY300_QL70_FMwebp_.jpg | R15: https://www.amazon.in/Portronics-Konnect-Delivery-Support-Braided/dp/B085DTN6R2/ref=sr_1_15?qid=1672909124&s=electronics&sr=1-15
A16: =LEFT(B16,LEN(B16)-1) -> B09KLVMZ3 | B16: B09KLVMZ3B | C16: =CONCATENATE(Sheet2!B16,Sheet2!C16) -> PortronicsKonnect | D16: Computers&Accessories | E16: $159 | F16: $399 | G16: 0.6 | H16: 4.1 | I16: 4768 | J16: [CHARGE & SYNC FUNCTION]- This cable comes with charging & Data sync function|[HIGH QUALITY MATERIAL]- TPE + Nylon Material to make sure that the life of the cable is enhanced significantly|[LONG CORD]- The Cable is extra thick 1.2 meter long, optimized for an easy use for your comfort at home or office|[MORE DURABLE]-This cable is unique interms of design and multi-use and is positioned to provide the best comfort and performance while using|[UNIVERSAL COMPATIBILITY]- Compatible with all devices like iPhone XS, X, XR, 8, 7, 6S, 6, 5S, iPad Pro, iPad mini and iPad Air | K16: AF2XXVO7JUBUVAOBTJ3MNH4DGUFQ,AH6VDJLLPBXKCWXMLBKMBCQ2ESGA,AE642RIGZIT2VPQJOLNUZ34QVWJQ,AFLHNKQH5UQZU3ATISKSMRE2KEDQ,AF2L4MCRCIDOOREQJN7QPQ4QBZCA,AGKLZ4SUHAU47KJXDVHBBEWJODUA,AHESCOYXLCXB56F4JO45X4CZQCYA,AGGHDE6KFZHEDUDJBD5R27AYMEWA | L16: =CONCATENATE(Sheet4!B16,Sheet4!C16) -> Deepaak Singhsiva k. | M16: =COUNTA(Sheet4!B16:K16) -> 8 | N16: R20XIOU25HEX80,R2X55FA2EEUEYM,R393Z224NBTDLN,R3Q4ZCHWSAQD5B,R1AE3A4NSVM9SC,R2U1YAAZE07I1V,R36NVL58WQ7D64,R1E7GPZ569TBIZ | O16: Great but,Worked well for 6 six months thatâ€™s it,Compatible with Apple iPad 2nd generation and charging very well.,CABLE,The product is good but the phone gets disconnected at multiple occasions.,Not a fast charging cable,Good item. Value,Amazing product and value for money | P16: Loosing charging cable of apple is costly affair. This wire was great purchase made to correct it,Worked well for six months thatâ€™s it, now itâ€™s stopped working, now planning to buy one more because the price has come down to 150,Very good product. Compatible with iPad 2nd generation and charging very well. Quality of the product is very good and also works fine. Totally worth for its price.,Product is super,I'm using from last 6 month. Till now it was good functioning. Now I noticed phone gets disconnected at multiple occasions. might be cable may be damaged.Overall worked well for 6 month.,Takes 5-6 hours to charge full.,Good item. Value,It is the best product I have used till now. | Q16: https://m.media-amazon.com/images/W/WEBP_402378-T2/images/I/41R08zLK69L._SX300_SY300_QL70_FMwebp_.jpg | R16: https://www.amazon.in/Portronics-Konnect-POR-1401-Charging-Function/dp/B09KLVMZ3B/ref=sr_1_16?qid=1672909124&s=electronics&sr=1-16
A17: =LEFT(B17,LEN(B17)-1) -> B083342NK | B17: B083342NKJ | C17: =CONCATENATE(Sheet2!B17,Sheet2!C17) -> MIBraided | D17: Computers&Accessories | E17: $349 | F17: $399 | G17: 0.13 | H17: 4.4 | I17: 18757 | J17: 1M Long Cable. Usb 2.0 (Type A)|Toughened Joints|Strong And Sturdy|Country Of Origin: China|6 Months Warranty | K17: AGSGSRTEZBQY64WO2HKQTV7TWFSA,AEYD5HVYAJ23CR6PTWOOIKUOIDHA,AFRMNW6TDHDZBP2UHF2K3MEAEYUA,AHICHCW6EC3BNV2IDAEAJPBG4HZQ,AGWFKE7RNP6EVC4JFLFSL76EEVVQ,AGEOQQHGNELZNEUKJAJUA7NTPBLA,AFS3QBSOMCE2FAZFUYZ3NBFQDLMQ,AGJYG6ZWCWD74WNE6Y37XZ2VUSMA | L17: =CONCATENATE(Sheet4!B17,Sheet4!C17) -> Birendra ku DashAditya Gupta | M17: =COUNTA(Sheet4!B17:K17) -> 8 | N17: R2JPQNKCOE10UK,RQI80JG2WZXNF,R2LYZ4CUWPMUJN,R1ZBD2ZB2ZYEWX,R2ITEDC9KOCY3N,R1115HIQP3BKKJ,R31OMS6DNMI7M,R2DCFXQMUNO93L | O17: Good product,using this product 8months It is done I have not faced any problem so far, its build quality best,I really liked this one.,Very strong and support fast charging ,,Nice cable,Best data cable charging fast,Good job,Good but need some improvement | P17: I like it ðŸ‘ðŸ‘,Best charging power . I used this cable on note 8 pro mi. Using 8month also fast working.,350 might be a little expensive but physically itâ€™s so good. Feels premium. But power limitation is there it is not suitable for fast charging.,,https://m.media-amazon.com/images/W/WEBP_402378-T1/images/I/61WnvIUaIwL._SY88.jpg,Best data cable charging fast,Very good quality and good durability,Overall good but need some improvement... | Q17: https://m.media-amazon.com/images/W/WEBP_402378-T1/images/I/31gaP7qpBNL._SX300_SY300_QL70_FMwebp_.jpg | R17: https://www.amazon.in/Mi-Braided-USB-Type-C-Cable/dp/B083342NKJ/ref=sr_1_17?qid=1672909124&s=electronics&sr=1-17
A18: =LEFT(B18,LEN(B18)-1) -> B0B6F7LX4 | B18: B0B6F7LX4C | C18: =CONCATENATE(Sheet2!B18,Sheet2!C18) -> MI80 | D18: Electronics | E18: $13,999 | F18: $24,999 | G18: 0.44 | H18: 4.2 | I18: 32840 | J18: Note : The brands, Mi and Xiaomi, are part of the same multinational conglomerate|Resolution : HD Ready (1366 x 768) Resolution | Refresh Rate : 60 Hertz | 178 Degree wide viewing angle|Connectivity: Dual Band Wi-Fi | 2 HDMI ports to connect latest gaming consoles, set top box, Blu-ray Players | 2 USB ports to connect hard drives and other USB devices | ALLM | ARC | Bluetooth 5.0 | Ethernet|Sound: 20 Watts Output | Dolby Audio, DTS Virtual: X, DTS-HD|Smart TV Features : Android TV 11 | PatchWall | IMDb Integration | Universal Search | 300+ Free Live Channels | Kids Mode with Parental lock | Smart Recommendations | Language Universe â€“ 15+ Languages | User Centre | Okay Google | Chromecast suporting Apps : Netflix, Prime Video, Disney+ Hotstar | 5000+ apps from Play Store |Quad core Cortex A35 | Chromecast built-in | Ok Google | Auto Low Latency Mode | 1GB RAM + 8GB Storage|Display: HD Ready | Vivid Picture Engine|Warranty Information: 1 year comprehensive warranty on product and 1 year additional on Panel provided by the brand from the date of purchase | K18: AHEVOQADJSSRX7DS325HSFLMP7VQ,AG7XYZRCSKX6G2OLO7DVZWIZ3PUQ,AE2THTCCQLBIUSWPF4CPXC6GGP7Q,AHUJZOV34DFEN55QQ5XOYKVKHV6Q,AELX4DI77ZHURZTDLYFU7XMP7R6Q,AE2ODWBBOBD2SITDDIEJ644OSRFQ,AFLW4WXYQ3G6HU5LBQORDDZO3FOQ,AGGRC2P6M43GDEWCAHGYAILCSKTQ | L18: =CONCATENATE(Sheet4!B18,Sheet4!C18) -> Manoj maddheshiyaManoj Kumar Sahoo | M18: =COUNTA(Sheet4!B18:K18) -> 8 | N18: R13UTIA6KOF6QV,R2UGDZSGFF01K7,RHHIZ45VYU5X6,R14N9HBE5EIUY0,R2WMW096T9Y0OU,R1SHIIE6M72825,R22P6BE9DBME4F,R2TEINENXTIHT2 | O18: It is the best tv if you are getting it in 10-12k,Good price but the OS lags,GARBAGE QUALITY,Good product.,Good quality,Great experience everything is fantastic ðŸ¤ ,Super picture quality and sound quality,Awesome | P18: Pros- xiomi 5a is best in budget-Nice picture quality-Very nice audio output- Full of featureCONS- sometimes tv lags-Sometimes stucksIn this prize range all tv having cons like this.::Overall nice tv,The product in this price range is good but as it is running in Android 12 it lags. I hope after few updates the lags problem will be resolved,Useless product and useless quality. Display issues within 7 months and service center is not upto the mark. Go for better brands where quality is assured. I would wish if there was option of negative stars.,Uses as connectes TV the picture is very good. I was hopping a best level of song. Globaly it is a good product.,https://m.media-amazon.com/images/I/61spXDbojZL._SY88.jpg,Greater then ever,Good quality,Good ðŸ‘ | Q18: https://m.media-amazon.com/images/I/51fmHk3km+L._SX300_SY300_.jpg | R18: https://www.amazon.in/MI-inches-Ready-Android-L32M7-5AIN/dp/B0B6F7LX4C/ref=sr_1_18?qid=1672909124&s=electronics&sr=1-18
A19: =LEFT(B19,LEN(B19)-1) -> B082LSVT4 | B19: B082LSVT4B | C19: =CONCATENATE(Sheet2!B19,Sheet2!C19) -> AmbraneUnbreakable | D19: Computers&Accessories | E19: $249 | F19: $399 | G19: 0.38 | H19: 4 | I19: 43994 | J19: Compatible with all Type C enabled devices, be it an android smartphone (Mi, Samsung, Oppo, Vivo, Realme, OnePlus, etc), tablet, laptop (Macbook, Chromebook, etc)|Unbreakable â€“ Made of special braided outer with rugged interior bindings, it is ultra-durable cable that wonâ€™t be affected by daily rough usage|Ideal Length â€“ It has ideal length of 1.5 meters which is neither too short like your typical 1meter cable or too long like a 2meters cable|Supports maximum 3A fast charging and 480 Mbps data transfer speed|6 months manufacturer warranty from the date of purchase | K19: AECPFYFQVRUWC3KGNLJIOREFP5LQ,AGYYVPDD7YG7FYNBXNGXZJT525AQ,AHONIZU3ICIEHQIGQ6R2VFRSBXOQ,AFPHD2CRPDZMWMBL7WXRSVYWS5JA,AEZ346GX3HJ4O4XNRPHCNHXQURMQ,AEPSWFPNECKO34PUC7I56ITGXR6Q,AHWVEHR5DYLVFTO2KF3IZATFQSWQ,AH4QT33M55677I7ISQOAKEQWACYQ | L19: =CONCATENATE(Sheet4!B19,Sheet4!C19) -> ArdKnNirbhay kumar | M19: =COUNTA(Sheet4!B19:K19) -> 8 | N19: RGIQEG07R9HS2,R1SMWZQ86XIN8U,R2J3Y1WL29GWDE,RYGGS0M09S3KY,R17KQRUTAN5DKS,R3AAQGS6HP2QUK,R1HDNOG6TO2CCA,R3PHKXYA5AFEOU | O19: A Good Braided Cable for Your Type C Device,Good quality product from ambrane,Super cable,As,Good quality,Good product,its good,Good quality for the price but one issue with my unit | P19: I ordered this cable to connect my phone to Android Auto of car. The cable is really strong and the connection ports are really well made. I already has a Micro USB cable from Ambrane and it's still in good shape. I connected my phone to the car using the cable and it got connected well and no issues. I also connected it to the charging port and yes it has Fast Charging support.,It quality is good at this price and the main thing is that i didn't ever thought that this cable will be so long it's good one and charging power is too good and also supports fast charging,Value for money, with extra lengthðŸ‘,Good, working fine,Product quality is good,Good,very good,Bought for my daughter's old phone.Brand new cable it was not charging, I already repacked and requested for replacement.I checked again, and there was some green colour paste/fungus inside the micro USB connector. I cleaned with an alcoholic and starts working again.Checked the ampere of charging speed got around 1400ma-1500ma - not bad, came with braided 1.5m long cable, pretty impressive for the price.Can't blame the manufacturer.But quality issues by the distributor, they might have stored in very humid place. | Q19: https://m.media-amazon.com/images/I/41d84o5-M-L._SY445_SX342_QL70_FMwebp_.jpg | R19: https://www.amazon.in/Ambrane-Unbreakable-Charging-Braided-Cable/dp/B082LSVT4B/ref=sr_1_19?qid=1672909124&s=electronics&sr=1-19
A20: =LEFT(B20,LEN(B20)-1) -> B08WRBG3X | B20: B08WRBG3XW | C20: =CONCATENATE(Sheet2!B20,Sheet2!C20) -> boAtType | D20: Computers&Accessories | E20: $199 | F20: $499 | G20: 0.6 | H20: 4.1 | I20: 13045 | J20: Type C A 325 Cable Is Designed With A Perfect 1.5 Meters In Length For Hassle Free Usage|It Dons Premium Braided Skin That Makes It Sturdy And Invincible Against External Damage With 10000+ Bends Lifespan The Cable Stays Stronger And Lasts Longer|Type C A 325 Offers Universal Compatibility With Smartphones, Tablets, Pc Peripherals, Bluetooth Speakers, Power Banks And All Other Devices With Type C Port|The Reversible Metallic Aluminium Tip Lets The User Connect Devices In A Carefree Manner|Its Flexible Design Offers The User A Tangle-Free Experience|2 years warranty from the date of purchase | K20: AFB5KJR4Q5FICAHBOPDPUTB3O7QQ,AHW3QBHDOUMXODZ4EAMHD5JMDIDQ,AGXRGH7DLS3RVFS5KWU4PGR3H3GQ,AFLIHOX2HH7S2OJAD63UAHKMY34Q,AEHBE4U3HD6G2TMSHKE7TNZYOWCA,AFHKIURZM4R62UEXTOCZLI2FPQ6A,AEW6K4E5A4RUWRFFUDINQE5WWBSQ,AG4LMDCRAAKD4U2FZ6B6N75KTHXA | L20: =CONCATENATE(Sheet4!B20,Sheet4!C20) -> Rohan NarkarJAGWINDER SINGH | M20: =COUNTA(Sheet4!B20:K20) -> 8 | N20: R2BP8Y5OJXKJLF,R218813TNRHNSY,R3VIKEVJ5DBF5G,R2PQNCTR8TQCT4,R3FI11UEJC9ZOJ,R3ULCCZZHBNLA4,RELIQ4H7CYX2Q,R3ALQNTJN4ER9N | O20: Good for charging and Data transfer,à¨®à¨œà¨¼à¨¬à©‚à¨¤,Good Quality but less Power Delivery,Fantastic!,Good,Not useful,Doesn't fit properly,Can't support Oppo mobile for fast charging | P20: Check for offera before buying,18w charging cable,,Awesome cable!Charging, data transfer and durability is simply awesome, and there is not a single disconnection issue, which I always faced in original mi cable from box. Bought 1 more time as last cable damaged when phone fell on usb cable port as my phone is heavy and I never faced any issues so i bought one more time and didn't went for replacement as its waste of time and energy, i also have boat earphones that is also awesome..ðŸ˜„,Good,Charging is very slow. Forget about fast charging. Not useful at all,Cable is not fit properly on my samsung galaxy m31 type C port. If little hit happens then cable is plug it out. Otherwise length and cable quality is very nice,Boat type C cable doesn't support fast charging on Oppo F15, earlier i was using Vooc cable, which worked excellent | Q20: https://m.media-amazon.com/images/W/WEBP_402378-T1/images/I/41xwPQLxTML._SX300_SY300_QL70_FMwebp_.jpg | R20: https://www.amazon.in/boAt-A325-Tangle-Free-Charging-Transmission/dp/B08WRBG3XW/ref=sr_1_20?qid=1672909124&s=electronics&sr=1-20
A21: =LEFT(B21,LEN(B21)-1) -> B08DPLCM6 | B21: B08DPLCM6T | C21: =CONCATENATE(Sheet2!B21,Sheet2!C21) -> LG80 | D21: Electronics | E21: $13,490 | F21: $21,990 | G21: 0.39 | H21: 4.3 | I21: 11976 | J21: Resolution: HD Ready (1366x768) | Refresh Rate: 50 hertz|Connectivity: 2 HDMI ports to connect set top box, Blu Ray players, gaming console | 1 USB ports to connect hard drives and other USB devices|Sound output: 10 Watts Output I 2 Speakers | DTS Virtual:X | Sound Type : Down Firing|Smart TV Features: Web OS Smart TV | Wi-Fi | Home Dashboard | Screen Mirroring | Mini TV Browser | Multi-Tasking | Office 365, Set WXHXD (with Stand ) mm - 739 x 472 x 168|Display: Active HDR | Display Type: Flat | BackLight Module: Slim LED|Warranty Information: 1 Year LG India Comprehensive Warranty and additional 1 year Warranty is applicable on panel/module from the date of purchase|Installation : For requesting installation/wall mounting/demo of this product once delivered, please directly call LG support (Please visit LG Website for Toll Free Numebrs) and provide product's model name as well as seller's details mentioned on the invoice | K21: AHBNKB74LGTYUOKPAJBSKNFV45CA,AFIECTV45ADX5YPTE2VU6ORRHTGQ,AFDUJI7KG7VMZF4JGJHV4DBCA4OA,AEUWKSX5ZL7DWOOYVDOWJKBHOVXA,AHEJW5MYVFOQBEXD6BIUBB3PJBPQ,AEM2Y22BKLFYL5BK7SC56Q75ODOQ,AHWDVB4OO4S3YS5RYQZIDBNV6BUQ,AFCEDQXVCB4LUUBWXRJS6KRU62FQ | L21: =CONCATENATE(Sheet4!B21,Sheet4!C21) -> NIRMAL.NManoj kumar | M21: =COUNTA(Sheet4!B21:K21) -> 8 | N21: R2PNR69G0BQG2F,R31A0WWDEYMKEW,R2C4XEWFLVU7JV,RYWES5AT5FQO6,R1PGWAY5TEWLT4,R32542OPR0QC4I,R2JDJEVZ2G7EEK,R36EHHPAQNSSOF | O21: Sound quality,Very nice,Value for money,Good,Good for its price.,Good item,Budget friendly,Good | P21: LG was always Good , correct delivery, good service but sound quality was poor. The speakers were fitted below the tv. No clear sound. That was the only problem.,Good videoGood vice,Picture quality is awesome.,Good at that price,Okay product, the OS has lags after about a year of use. This is the best you can get for the price tag it comes with.,I like it,Best one when it comes to bugdet, easy installation and handy features.,Good | Q21: https://m.media-amazon.com/images/W/WEBP_402378-T2/images/I/51v-2Nzr+ML._SY300_SX300_.jpg | R21: https://www.amazon.in/LG-inches-Ready-Smart-32LM563BPTC/dp/B08DPLCM6T/ref=sr_1_21?qid=1672909124&s=electronics&sr=1-21
A22: =LEFT(B22,LEN(B22)-1) -> B09C6HXFC | B22: B09C6HXFC1 | C22: =CONCATENATE(Sheet2!B22,Sheet2!C22) -> DuracellUSB | D22: Computers&Accessories | E22: $970 | F22: $1,799 | G22: 0.46 | H22: 4.5 | I22: 815 | J22: Supports Ios Devices With Max Output Up To 2.4A|Up To 10, 000+ Bend And 10, 000+ Plugging And Unplugging Test Ensure This Cable A Longer Lifespan|Ensure Fast And Stable Data Transmission Up To 480 Mbps|2 Years Warranty|Compatible Designed To Work Flawlessly With Mfi Or Apple Devices, Iphone, Imac, Ipad Etc|1.2M Tangle Free Durable Tough Braiding Sync & Charge Cable | K22: AFNYIBWKJLJQKY4BGK77ZOTVMORA,AFCTNNMP2LZLY5466YJ5AY3JE5ZA,AG3XBWOAL65DJSBHJ7LQ2K54HJKQ,AF2ZFMLJS4UBCGZO4FMJTEPP6MHA,AFBZMRHC4GXUU7KNAK4OBKORDF6Q,AHSIQL276K7X2UP72QOOOWNVRSXA,AF3D6X5NQWOBOEVVH2Y37N55AKZQ,AFWOTSQXCQJLZ653Y7ACEZADKGYQ | L22: =CONCATENATE(Sheet4!B22,Sheet4!C22) -> Prasannavijayaraghavan G.Preet Sikka | M22: =COUNTA(Sheet4!B22:K22) -> 8 | N22: R12D1BZF9MU8TN,R32MNCWO5LGFCG,RZU3UK8OZKD6X,R3BSTKR3JUW6GY,R1ARVYPXS4XPB7,R1V6GDYE2IBX8O,R28EG2PXZTJL90,R2SQNU7OIOOLHT | O22: Good cable for car,Good substitute for orginal,Better Value for money Product,Way better than the original,Absolutely amazing.,Namm hi kafi hai,Very good,As the names say Durable cell it a durable cable ;-) | P22: I trust this product! Works well with car play!,Very good quality and charging is fine. As good as original,Build quality is awesome, best lightening cable ever seen, better than a official lightening from ï£¿If ur looking for a cable close your eyes and go for it ðŸ”¥ or you can buy a (Amazon basics) one I was using that for past 3 years that a bit a cheaper side, I recommend both these cables had better build quality and value for money,Gr8 product overall,Just loved it, very good charging speed.,,Good quality,it well packed, all sealed coveredthe wire looks of a very good qualityrecommended!!!! | Q22: https://m.media-amazon.com/images/W/WEBP_402378-T1/images/I/41TZJiPRRwL._SX300_SY300_QL70_FMwebp_.jpg | R22: https://www.amazon.in/DURACELL-Lightning-Certified-braided-Devices/dp/B09C6HXFC1/ref=sr_1_22?qid=1672909124&s=electronics&sr=1-22
